============================= test session starts =============================
platform win32 -- Python 3.9.12, pytest-7.2.0, pluggy-1.0.0
rootdir: C:\Users\advod\AAA\python\git\aaa-final-task
collected 4 items

issue-03_ohe_unittest.py ...F                                            [100%]

================================== FAILURES ===================================
____________________________ TestOHE.test_numbers _____________________________

self = <issue-03_ohe_unittest.TestOHE testMethod=test_numbers>

    def test_numbers(self):
        actual = fit_transform([1, 2, 3, 4, 2, 3])
        expected = [(1, [0, 0, 0, 1]),
                    (2, [0, 0, 1, 0]),
                    (3, [0, 1, 0, 0]),
                    (4, [1, 0, 0, 0]),
                    (2, [0, 0, 1, 0])]
>       self.assertEqual(actual, expected)
E       AssertionError: Lists differ: [(1, [46 chars], 0]), (4, [1, 0, 0, 0]), (2, [0, 0, 1, 0]), (3, [0, 1, 0, 0])] != [(1, [46 chars], 0]), (4, [1, 0, 0, 0]), (2, [0, 0, 1, 0])]
E       
E       First list contains 1 additional elements.
E       First extra element 5:
E       (3, [0, 1, 0, 0])
E       
E         [(1, [0, 0, 0, 1]),
E          (2, [0, 0, 1, 0]),
E          (3, [0, 1, 0, 0]),
E          (4, [1, 0, 0, 0]),
E       -  (2, [0, 0, 1, 0]),
E       ?                   ^
E       
E       +  (2, [0, 0, 1, 0])]
E       ?                   ^
E       
E       -  (3, [0, 1, 0, 0])]

issue-03_ohe_unittest.py:22: AssertionError
=========================== short test summary info ===========================
FAILED issue-03_ohe_unittest.py::TestOHE::test_numbers - AssertionError: List...
========================= 1 failed, 3 passed in 0.40s =========================
